Traceback (most recent call last):
  File "/opt/hostedtoolcache/Python/3.8.13/x64/lib/python3.8/site-packages/jupyter_cache/executors/utils.py", line 51, in single_nb_execution
    executenb(
  File "/opt/hostedtoolcache/Python/3.8.13/x64/lib/python3.8/site-packages/nbclient/client.py", line 1204, in execute
    return NotebookClient(nb=nb, resources=resources, km=km, **kwargs).execute()
  File "/opt/hostedtoolcache/Python/3.8.13/x64/lib/python3.8/site-packages/nbclient/util.py", line 84, in wrapped
    return just_run(coro(*args, **kwargs))
  File "/opt/hostedtoolcache/Python/3.8.13/x64/lib/python3.8/site-packages/nbclient/util.py", line 62, in just_run
    return loop.run_until_complete(coro)
  File "/opt/hostedtoolcache/Python/3.8.13/x64/lib/python3.8/asyncio/base_events.py", line 616, in run_until_complete
    return future.result()
  File "/opt/hostedtoolcache/Python/3.8.13/x64/lib/python3.8/site-packages/nbclient/client.py", line 663, in async_execute
    await self.async_execute_cell(
  File "/opt/hostedtoolcache/Python/3.8.13/x64/lib/python3.8/site-packages/nbclient/client.py", line 965, in async_execute_cell
    await self._check_raise_for_error(cell, cell_index, exec_reply)
  File "/opt/hostedtoolcache/Python/3.8.13/x64/lib/python3.8/site-packages/nbclient/client.py", line 862, in _check_raise_for_error
    raise CellExecutionError.from_cell_and_msg(cell, exec_reply_content)
nbclient.exceptions.CellExecutionError: An error occurred while executing the following cell:
------------------
# load WOA18 data
obs_path = '/glade/u/home/gmarques/Notebooks/CESM_MOM6/WOA18_remapping/'
obs_temp = xr.open_dataset(obs_path+'WOA18_TEMP_tx0.66v1_34lev_ann_avg.nc', decode_times=False)
obs_salt = xr.open_dataset(obs_path+'WOA18_SALT_tx0.66v1_34lev_ann_avg.nc', decode_times=False)
# get theta and salt and rename coordinates to be the same as the model's
thetao_obs = obs_temp.theta0.rename({'z_l': 'zl'});
salt_obs = obs_salt.s_an.rename({'z_l': 'zl'});
salt_obs['yh'] = grd.yh
thetao_obs['yh'] = grd.yh
------------------

[0;31m---------------------------------------------------------------------------[0m
[0;31mNameError[0m                                 Traceback (most recent call last)
Input [0;32mIn [2][0m, in [0;36m<cell line: 3>[0;34m()[0m
[1;32m      1[0m [38;5;66;03m# load WOA18 data[39;00m
[1;32m      2[0m obs_path [38;5;241m=[39m [38;5;124m'[39m[38;5;124m/glade/u/home/gmarques/Notebooks/CESM_MOM6/WOA18_remapping/[39m[38;5;124m'[39m
[0;32m----> 3[0m obs_temp [38;5;241m=[39m [43mxr[49m[38;5;241m.[39mopen_dataset(obs_path[38;5;241m+[39m[38;5;124m'[39m[38;5;124mWOA18_TEMP_tx0.66v1_34lev_ann_avg.nc[39m[38;5;124m'[39m, decode_times[38;5;241m=[39m[38;5;28;01mFalse[39;00m)
[1;32m      4[0m obs_salt [38;5;241m=[39m xr[38;5;241m.[39mopen_dataset(obs_path[38;5;241m+[39m[38;5;124m'[39m[38;5;124mWOA18_SALT_tx0.66v1_34lev_ann_avg.nc[39m[38;5;124m'[39m, decode_times[38;5;241m=[39m[38;5;28;01mFalse[39;00m)
[1;32m      5[0m [38;5;66;03m# get theta and salt and rename coordinates to be the same as the model's[39;00m

[0;31mNameError[0m: name 'xr' is not defined
NameError: name 'xr' is not defined

