Traceback (most recent call last):
  File "/opt/hostedtoolcache/Python/3.8.13/x64/lib/python3.8/site-packages/jupyter_cache/executors/utils.py", line 51, in single_nb_execution
    executenb(
  File "/opt/hostedtoolcache/Python/3.8.13/x64/lib/python3.8/site-packages/nbclient/client.py", line 1204, in execute
    return NotebookClient(nb=nb, resources=resources, km=km, **kwargs).execute()
  File "/opt/hostedtoolcache/Python/3.8.13/x64/lib/python3.8/site-packages/nbclient/util.py", line 84, in wrapped
    return just_run(coro(*args, **kwargs))
  File "/opt/hostedtoolcache/Python/3.8.13/x64/lib/python3.8/site-packages/nbclient/util.py", line 62, in just_run
    return loop.run_until_complete(coro)
  File "/opt/hostedtoolcache/Python/3.8.13/x64/lib/python3.8/asyncio/base_events.py", line 616, in run_until_complete
    return future.result()
  File "/opt/hostedtoolcache/Python/3.8.13/x64/lib/python3.8/site-packages/nbclient/client.py", line 663, in async_execute
    await self.async_execute_cell(
  File "/opt/hostedtoolcache/Python/3.8.13/x64/lib/python3.8/site-packages/nbclient/client.py", line 965, in async_execute_cell
    await self._check_raise_for_error(cell, cell_index, exec_reply)
  File "/opt/hostedtoolcache/Python/3.8.13/x64/lib/python3.8/site-packages/nbclient/client.py", line 862, in _check_raise_for_error
    raise CellExecutionError.from_cell_and_msg(cell, exec_reply_content)
nbclient.exceptions.CellExecutionError: An error occurred while executing the following cell:
------------------
transports = []
for path, case in zip(ocn_path, casename):
  ds = xr.open_dataset(path+case+'_section_transports.nc')
  transports.append(ds)
------------------

[0;31m---------------------------------------------------------------------------[0m
[0;31mNameError[0m                                 Traceback (most recent call last)
Input [0;32mIn [2][0m, in [0;36m<cell line: 2>[0;34m()[0m
[1;32m      1[0m transports [38;5;241m=[39m []
[0;32m----> 2[0m [38;5;28;01mfor[39;00m path, case [38;5;129;01min[39;00m [38;5;28mzip[39m([43mocn_path[49m, casename):
[1;32m      3[0m   ds [38;5;241m=[39m xr[38;5;241m.[39mopen_dataset(path[38;5;241m+[39mcase[38;5;241m+[39m[38;5;124m'[39m[38;5;124m_section_transports.nc[39m[38;5;124m'[39m)
[1;32m      4[0m   transports[38;5;241m.[39mappend(ds)

[0;31mNameError[0m: name 'ocn_path' is not defined
NameError: name 'ocn_path' is not defined

